Rust 将错误分为两大类：可恢复的（recoverable）和 不可恢复的（unrecoverable）错误。
对于一个可恢复的错误，比如文件未找到的错误，我们很可能只想向用户报告问题并重试操作。
不可恢复的错误总是 bug 出现的征兆，比如试图访问一个超过数组末端的位置，因此我们要立即停止程序。

Rust 使用 `Result<T, E>` 类型处理可恢复的错误；使用 `panic!` 宏在程序遇到不可恢复的错误时停止执行。

## 用 panic! 处理不可恢复的错误

在实践中有两种方法造成 panic：执行会造成代码 panic 的操作或者显式调用 `panic!` 宏。

```rust
let v = vec![1, 2, 3];
// 数组访问越界，被动触发 panic
v[99];

panic!("主动调用 panic");
```

panic! 宏会打印出一个错误信息，展开报错点往前的函数调用堆栈，最后退出程序。

## 处理可恢复的错误

可以使用 `Result<T, E>` 类型来处理可恢复的错误。`Result<T, E>` 类型是一个枚举
类型，它有 `Ok(T)` 和 `Err(E)` 两个值。

```rust
use std::fs::File;
use std::io::ErrorKind;
let greeting_file_result = File::open("hello.txt");
let greeting_file = match greeting_file_result {
    Ok(file) => file, // 如果 greeting_file_result 是 Ok，则返回 file
    Err(err) => match err.kind() {
        ErrorKind::NotFound => match File::create("hello.txe") {
            Ok(fc) => fc,
            Err(err) => panic!("创建文件失败: {err:?}"),
        },
        other_error => {
            panic!("打开文件失败：{other_error:?}")
        }
    },
};
```

使用 `Result<T, E>` 类型处理可恢复的错误，可以使程序更加友好。

## 错误传播

一般情况下，我们并不需要处理错误，而是让调用者处理错误，这时就需要将错误传播给调用者。

```rust
fn read_username_from_file_1() -> Result<String, io::Error> {
    let username_file_result = File::open("hello.txt");
    let mut username_file = match username_file_result {
        Ok(file) => file,
        Err(e) => return Err(e), // 错误传播
    };
    let mut username = String::new();
    match username_file.read_to_string(&mut username) {
        Ok(_) => Ok(username),
        Err(e) => Err(e), // 错误传播
    }
}
```

由于错误传播使用比较频繁，因此可以使用 `?` 运算符来简化代码。

```rust
fn read_username_from_file_2() -> Result<String, io::Error> {
    let mut username = String::new();
    // 如果返回 Ok 则继续执行，否则将 Err 返回；
    // 可以直接在 ? 之后使用链式方法调用。
    File::open("hello.txt")?.read_to_end(&mut username);
    Ok(username)
}
```
在返回 `Result` 或 `Option` 的函数中可以使用 `?` 运算符。


## 使用 panic! 处理时机

- 示例、代码原型和测试都非常适合 panic。
- 当你能确切直到程序是正确时，可以使用 panic 。
- 在当有可能会导致有害状态的情况下建议使用 panic 。
- 创建自定义类型进行有效性验证时，使用 panic 可以有助于提前发现程序中的错误。

```rust
// parse 肯定能成功，所以不会 panic。所以可以使用 panic! 处理。
let home: IpAddr = "127.0.0.1".parse().unwrap();

// 自定义类型，限制值的取值范围为 1 到 100 之间。
pub struct Guess {
    value: i32,
}

impl Guess {
    pub fn new(value: i32) -> Guess {
        if value < 1 || value > 100 {
            // 如果值不在 1 到 100 之间，则调用 panic!，
            // 说明调用这个函数有 bug 。
            panic!("Guess value must be between 1 and 100, got {value}");
        }
        Guess { value }
    }
    pub fn value(&self) -> i32 {
        self.value
    }
}
```
